Workbook

Sheet Como usar
A1: Como usar esta planilha
A3: 1. Na aba Clientes, comece pela Prioridade A (filtre a coluna Prioridade). A = pequeno e independente, com celular/WhatsApp. B = só fixo, sem número público ou que talvez já tenha sistema.
A4: 2. Toque em "Abrir" na coluna Mensagem pronta: abre o WhatsApp do lugar já com a primeira mensagem escrita.
A5: 3. Depois de mandar, mude a coluna Status (lista suspensa) e preencha Data do contato, Próximo passo e Data do próximo passo. A linha muda de cor conforme o status.
A6: 4. A Data do próximo passo fica vermelha quando chega o dia: é hora do follow-up.
A7: 5. A aba Resumo conta tudo sozinha (respostas, testes, clientes fechados e receita).
A9: Colunas para você preencher: Status, Data do contato, Próximo passo, Data do próximo passo.
A10: Exemplo de preenchimento: Status = Mensagem enviada · Data do contato = 21/10/2026 · Próximo passo = Mandar vídeo se responder · Data do próximo passo = 23/10/2026
A12: Limites: contatos tirados de sites, guias locais e perfis públicos em 20/10/2026 (link em Fonte); alguns podem estar desatualizados. Mande no máximo 20 a 30 mensagens por dia, uma por uma, para o WhatsApp não bloquear o número.

Sheet Clientes
A1: Nº | B1: Prioridade | C1: Tipo | D1: Nome | E1: Cidade | F1: UF | G1: Bairro | H1: WhatsApp / Telefone | I1: Mensagem pronta | J1: Instagram / Site | K1: Observação | L1: Status | M1: Data do contato | N1: Próximo passo | O1: Data do próximo passo | P1: Fonte
A2: 1 | B2: A | C2: Futebol | D2: Ceti Piracicaba (Clube dos Metalúrgicos) | E2: Piracicaba | F2: SP | G2: Clube dos Metalúrgicos | H2: (19) 98808-7009 | I2: Abrir | K2: Falar com Edlaine. 5 a 16 anos, mensalidade R$80 a R$130. | L2: Não contatado | P2: Ver
A3: 2 | B3: A | C3: Futebol | D3: Escola de Futebol Coach Pro Arena | E3: Jundiaí | F3: SP | H3: (11) 99962-0007 | I3: Abrir | K3: Contato de guia local (sem data). | L3: Não contatado | P3: Ver
A4: 3 | B4: A | C4: Futebol | D4: Escola de Futebol MBrasil | E4: Jundiaí | F4: SP | H4: (11) 99599-6190 | I4: Abrir | K4: Outro número: (11) 96201-0933. | L4: Não contatado | P4: Ver
A5: 4 | B5: A | C5: Futebol | D5: APAFUT - Academia Porto Alegrense de Futebol | E5: Porto Alegre | F5: RS | G5: Tristeza | H5: (51) 99181-6479 | I5: Abrir | J5: apafut.com.br | K5: Matrículas 2026 abertas, dentro da FC Arena Soccer. | L5: Não contatado | P5: Ver
A6: 5 | B6: A | C6: Academia | D6: Lion Gym Fitness Center | E6: Uberlândia | F6: MG | G6: Centro | H6: (34) 99296-6601 | I6: Abrir | J6: facebook.com/liongymuberlandia | K6: Musculação e funcional. | L6: Não contatado | P6: Ver
A7: 6 | B7: A | C7: Academia | D7: Fix Pilates e Fisioterapia | E7: Ribeirão Preto | F7: SP | G7: Centro | H7: (16) 99223-5763 | I7: Abrir | J7: studiofixpilatesrp.wixsite.com | K7: Outro número: (16) 98112-4606. | L7: Não contatado | P7: Ver
A8: 7 | B8: A | C8: Academia | D8: Studio Fit Pilates | E8: Ribeirão Preto | F8: SP | G8: Nova Ribeirânia | H8: (16) 98231-1550 | I8: Abrir | K8: Pilates, fisioterapia e estética. | L8: Não contatado | P8: Ver
A9: 8 | B9: A | C9: Academia | D9: Espaço Vita Personal e Pilates | E9: Ribeirão Preto | F9: SP | H9: (16) 98844-8832 | I9: Abrir | K9: Contato de diretório, pode estar desatualizado. | L9: Não contatado | P9: Ver
A10: 9 | B10: A | C10: Academia | D10: Studio Paulo Otacílio (pilates e funcional) | E10: São José do Rio Preto | F10: SP | G10: Vila São José | H10: (17) 98222-2267 | I10: Abrir | K10: Seg a sex, 8h às 20h. | L10: Não contatado | P10: Ver
A11: 10 | B11: A | C11: Academia | D11: Studio Marília Bega Pilates | E11: São José do Rio Preto | F11: SP | G11: Parque Damha | H11: (17) 99123-0579 | I11: Abrir | J11: pilatesriopreto.net | K11: Oferece aula experimental. | L11: Não contatado | P11: Ver
A12: 11 | B12: A | C12: Lutas | D12: Dojo Kanashiro | E12: Goiânia | F12: GO | G12: Setor Marista | H12: (62) 98209-4340 | I12: Abrir | J12: @dojokanashiro | K12: Karatê, judô, jiu-jitsu, muay thai. | L12: Não contatado | P12: Ver
A13: 12 | B13: A | C13: Lutas | D13: Academia FT 38 | E13: Goiânia | F13: GO | H13: (62) 98127-0596 | I13: Abrir | J13: ft38.com.br | K13: Cross, boxe, muay thai, jiu-jitsu, judô. | L13: Não contatado | P13: Ver
A14: 13 | B14: A | C14: Lutas | D14: Budokan Academia | E14: Goiânia | F14: GO | H14: (62) 98295-6288 | I14: Abrir | J14: @budokan.academia | K14: Jiu-jitsu e judô. | L14: Não contatado | P14: Ver
A15: 14 | B15: A | C15: Lutas | D15: Black Thai | E15: Goiânia | F15: GO | H15: (62) 98296-4847 | I15: Abrir | K15: Muay thai. | L15: Não contatado | P15: Ver
A16: 15 | B16: A | C16: Lutas | D16: Villa Real Muay Thai | E16: Goiânia | F16: GO | H16: (62) 98610-9336 | I16: Abrir | K16: Muay thai. | L16: Não contatado | P16: Ver
A17: 16 | B17: A | C17: Lutas | D17: Hanuman Escola de Muaythai | E17: Goiânia | F17: GO | H17: (62) 98158-6537 | I17: Abrir | J17: @hanuman.mp | K17: Muay thai. | L17: Não contatado | P17: Ver
A18: 17 | B18: A | C18: Lutas | D18: Fight Sports Club Goiânia | E18: Goiânia | F18: GO | H18: (62) 98159-3223 | I18: Abrir | K18: Jiu-jitsu e muay thai. | L18: Não contatado | P18: Ver
A19: 18 | B19: A | C19: Lutas | D19: Schima Combat | E19: Maringá | F19: PR | G19: Av. Morangueira | H19: (44) 99732-8817 | I19: Abrir | J19: @schimacombat | K19: Muay thai, boxe, jiu-jitsu, krav maga. | L19: Não contatado | P19: Ver
A20: 19 | B20: A | C20: Lutas | D20: Clube Feijão Team | E20: Maringá | F20: PR | G20: Rua Saldanha Marinho | H20: (44) 99108-3530 | I20: Abrir | J20: @clubefeijaojj_team | K20: Jiu-jitsu. Fixo: (44) 3346-3497. | L20: Não contatado | P20: Ver
A21: 20 | B21: A | C21: Lutas | D21: Magoo Jiu-Jitsu | E21: Londrina | F21: PR | H21: (43) 99116-3738 | I21: Abrir | J21: @magoojiujitsu | K21: Aulas para crianças e adultos. | L21: Não contatado | P21: Ver
A22: 21 | B22: A | C22: Lutas | D22: Titans MMA | E22: Londrina | F22: PR | H22: (43) 99120-4510 | I22: Abrir | J22: facebook.com/titansmmabr | K22: Jiu-jitsu e muay thai. | L22: Não contatado | P22: Ver
A23: 22 | B23: A | C23: Dança | D23: Dance Sempre / Dance Show | E23: Curitiba | F23: PR | G23: Centro | H23: (41) 98816-0900 | I23: Abrir | J23: @dancesemprecuritiba | K23: Fixo: (41) 3023-1553. | L23: Não contatado | P23: Ver
A24: 23 | B24: A | C24: Dança | D24: Believe Studio de Dança | E24: Curitiba | F24: PR | G24: Al. Dom Pedro II | H24: (41) 99136-9977 | I24: Abrir | J24: @believestudiodedanca | K24: Fixo: (41) 3434-2030. | L24: Não contatado | P24: Ver
A25: 24 | B25: A | C25: Dança | D25: Flor de Lótus (dança e yoga) | E25: Curitiba | F25: PR | H25: (41) 99186-1501 | I25: Abrir | J25: estudioflordelotus.com | K25: Dança infantil a partir de 3 anos. | L25: Não contatado | P25: Ver
A26: 25 | B26: A | C26: Dança | D26: Baillarine Ballet | E26: Florianópolis | F26: SC | G26: Rod. Antônio Luiz Moura Gonzaga | H26: (48) 99644-1123 | I26: Abrir | J26: baillarineballet.com.br | K26: Balé de 4 a 10 anos. | L26: Não contatado | P26: Ver
A27: 26 | B27: A | C27: Dança | D27: DUO Escola de Dança | E27: Campo Grande | F27: MS | G27: Rua da Paz | H27: (67) 99168-5516 | I27: Abrir | J27: duoescoladedanca.com | K27: Balé, jazz, danças urbanas. | L27: Não contatado | P27: Ver
A28: 27 | B28: A | C28: Natação | D28: Academia Flipper | E28: Belo Horizonte | F28: MG | G28: Castelo | H28: (31) 97574-8477 | I28: Abrir | J28: flipperacademia.com.br | K28: Aula experimental grátis pelo WhatsApp. | L28: Não contatado | P28: Ver
A29: 28 | B29: A | C29: Natação | D29: Academia WB | E29: Belo Horizonte | F29: MG | G29: Sion | H29: (31) 99568-5283 | I29: Abrir | J29: academiawb.com.br | K29: Fixo: (31) 3281-2633. | L29: Não contatado | P29: Ver
A30: 29 | B30: A | C30: Cursos | D30: Apreender (reforço escolar e contraturno) | E30: Sorocaba | F30: SP | G30: Jd. Guadalajara | H30: (15) 99279-7968 | I30: Abrir | K30: Reforço escolar. | L30: Não contatado | P30: Ver
A31: 30 | B31: A | C31: Cursos | D31: Parábola Educacional | E31: Sorocaba | F31: SP | H31: (15) 99698-7765 | I31: Abrir | K31: Reforço escolar. | L31: Não contatado | P31: Ver
A32: 31 | B32: A | C32: Cursos | D32: LONI Escola de Inglês | E32: Sorocaba | F32: SP | H32: (15) 99765-1556 | I32: Abrir | K32: Inglês. | L32: Não contatado | P32: Ver
A33: 32 | B33: A | C33: Cursos | D33: Musix Academia de Música | E33: Sorocaba | F33: SP | G33: Jd. Paulistano | H33: (15) 99770-7017 | I33: Abrir | K33: Música. | L33: Não contatado | P33: Ver
A34: 33 | B34: A | C34: Cursos | D34: Escola Mais QI | E34: Campinas | F34: SP | G34: Av. das Amoreiras | H34: (19) 3272-8187 | I34: Abrir | J34: escolamaisqi.com | K34: Música, inglês e reforço. Número é telefone e WhatsApp. | L34: Não contatado | P34: Ver
A35: 34 | B35: B | C35: Futebol | D35: Escolinha de Futsal Treinador Miguel Cândido | E35: Recife | F35: PE | G35: Tamarineira | H35: (81) 3265-3039 | I35: — | K35: Só telefone fixo: ligar. | L35: Não contatado | P35: Ver
A36: 35 | B36: B | C36: Futebol | D36: Escola de Futebol Boca Juniors Campos Elíseos | E36: Campinas | F36: SP | G36: Jd. Campos Elíseos | H36: — | I36: — | J36: bocajuniorscamposeliseos.com.br | K36: Sem telefone no site. Escola licenciada de marca: pode já usar sistema da rede. | L36: Não contatado | P36: Ver
A37: 36 | B37: B | C37: Academia | D37: Cross Mov | E37: Ribeirão Preto | F37: SP | H37: (16) 3514-9715 | I37: — | K37: Só telefone fixo. | L37: Não contatado | P37: Ver
A38: 37 | B38: B | C38: Academia | D38: Bio Wellness Fitness Studio | E38: São José do Rio Preto | F38: SP | G38: Jd. Panorama | H38: (17) 3301-4533 | I38: — | J38: biowellnessstudio.com.br | K38: Só telefone fixo. | L38: Não contatado | P38: Ver
A39: 38 | B39: B | C39: Academia | D39: Academia Universal | E39: Joinville | F39: SC | G39: Iririú | H39: — | I39: — | J39: universalacademia.com.br | K39: WhatsApp no site. | L39: Não contatado | P39: Ver
A40: 39 | B40: B | C40: Academia | D40: Eisenfit | E40: Joinville | F40: SC | G40: Anita Garibaldi | H40: — | I40: — | J40: eisenfit.com.br | K40: Contato no site. | L40: Não contatado | P40: Ver
...

Sheet Resumo
A1: Resumo da prospecção
A2: Atualiza sozinho conforme você muda a coluna Status na aba Clientes.
A4: Tipo | B4: Total | C4: Prioridade A | D4: Não contatado | E4: Mensagem enviada | F4: Respondeu | G4: Vídeo/demo enviado | H4: Teste grátis | I4: Fechou (cliente) | J4: Sem interesse | K4: Número errado
A5: Futebol | B5: =COUNTIF(Clientes!$C:$C,$A5) -> 6 | C5: =COUNTIFS(Clientes!$C:$C,$A5,Clientes!$B:$B,"A") -> 4 | D5: =COUNTIFS(Clientes!$C:$C,$A5,Clientes!$L:$L,D$4) -> 6 | E5: =COUNTIFS(Clientes!$C:$C,$A5,Clientes!$L:$L,E$4) -> 0 | F5: =COUNTIFS(Clientes!$C:$C,$A5,Clientes!$L:$L,F$4) -> 0 | G5: =COUNTIFS(Clientes!$C:$C,$A5,Clientes!$L:$L,G$4) -> 0 | H5: =COUNTIFS(Clientes!$C:$C,$A5,Clientes!$L:$L,H$4) -> 0 | I5: =COUNTIFS(Clientes!$C:$C,$A5,Clientes!$L:$L,I$4) -> 0 | J5: =COUNTIFS(Clientes!$C:$C,$A5,Clientes!$L:$L,J$4) -> 0 | K5: =COUNTIFS(Clientes!$C:$C,$A5,Clientes!$L:$L,K$4) -> 0
A6: Academia | B6: =COUNTIF(Clientes!$C:$C,$A6) -> 12 | C6: =COUNTIFS(Clientes!$C:$C,$A6,Clientes!$B:$B,"A") -> 6 | D6: =COUNTIFS(Clientes!$C:$C,$A6,Clientes!$L:$L,D$4) -> 12 | E6: =COUNTIFS(Clientes!$C:$C,$A6,Clientes!$L:$L,E$4) -> 0 | F6: =COUNTIFS(Clientes!$C:$C,$A6,Clientes!$L:$L,F$4) -> 0 | G6: =COUNTIFS(Clientes!$C:$C,$A6,Clientes!$L:$L,G$4) -> 0 | H6: =COUNTIFS(Clientes!$C:$C,$A6,Clientes!$L:$L,H$4) -> 0 | I6: =COUNTIFS(Clientes!$C:$C,$A6,Clientes!$L:$L,I$4) -> 0 | J6: =COUNTIFS(Clientes!$C:$C,$A6,Clientes!$L:$L,J$4) -> 0 | K6: =COUNTIFS(Clientes!$C:$C,$A6,Clientes!$L:$L,K$4) -> 0
A7: Lutas | B7: =COUNTIF(Clientes!$C:$C,$A7) -> 12 | C7: =COUNTIFS(Clientes!$C:$C,$A7,Clientes!$B:$B,"A") -> 11 | D7: =COUNTIFS(Clientes!$C:$C,$A7,Clientes!$L:$L,D$4) -> 12 | E7: =COUNTIFS(Clientes!$C:$C,$A7,Clientes!$L:$L,E$4) -> 0 | F7: =COUNTIFS(Clientes!$C:$C,$A7,Clientes!$L:$L,F$4) -> 0 | G7: =COUNTIFS(Clientes!$C:$C,$A7,Clientes!$L:$L,G$4) -> 0 | H7: =COUNTIFS(Clientes!$C:$C,$A7,Clientes!$L:$L,H$4) -> 0 | I7: =COUNTIFS(Clientes!$C:$C,$A7,Clientes!$L:$L,I$4) -> 0 | J7: =COUNTIFS(Clientes!$C:$C,$A7,Clientes!$L:$L,J$4) -> 0 | K7: =COUNTIFS(Clientes!$C:$C,$A7,Clientes!$L:$L,K$4) -> 0
A8: Dança | B8: =COUNTIF(Clientes!$C:$C,$A8) -> 7 | C8: =COUNTIFS(Clientes!$C:$C,$A8,Clientes!$B:$B,"A") -> 5 | D8: =COUNTIFS(Clientes!$C:$C,$A8,Clientes!$L:$L,D$4) -> 7 | E8: =COUNTIFS(Clientes!$C:$C,$A8,Clientes!$L:$L,E$4) -> 0 | F8: =COUNTIFS(Clientes!$C:$C,$A8,Clientes!$L:$L,F$4) -> 0 | G8: =COUNTIFS(Clientes!$C:$C,$A8,Clientes!$L:$L,G$4) -> 0 | H8: =COUNTIFS(Clientes!$C:$C,$A8,Clientes!$L:$L,H$4) -> 0 | I8: =COUNTIFS(Clientes!$C:$C,$A8,Clientes!$L:$L,I$4) -> 0 | J8: =COUNTIFS(Clientes!$C:$C,$A8,Clientes!$L:$L,J$4) -> 0 | K8: =COUNTIFS(Clientes!$C:$C,$A8,Clientes!$L:$L,K$4) -> 0
A9: Natação | B9: =COUNTIF(Clientes!$C:$C,$A9) -> 6 | C9: =COUNTIFS(Clientes!$C:$C,$A9,Clientes!$B:$B,"A") -> 2 | D9: =COUNTIFS(Clientes!$C:$C,$A9,Clientes!$L:$L,D$4) -> 6 | E9: =COUNTIFS(Clientes!$C:$C,$A9,Clientes!$L:$L,E$4) -> 0 | F9: =COUNTIFS(Clientes!$C:$C,$A9,Clientes!$L:$L,F$4) -> 0 | G9: =COUNTIFS(Clientes!$C:$C,$A9,Clientes!$L:$L,G$4) -> 0 | H9: =COUNTIFS(Clientes!$C:$C,$A9,Clientes!$L:$L,H$4) -> 0 | I9: =COUNTIFS(Clientes!$C:$C,$A9,Clientes!$L:$L,I$4) -> 0 | J9: =COUNTIFS(Clientes!$C:$C,$A9,Clientes!$L:$L,J$4) -> 0 | K9: =COUNTIFS(Clientes!$C:$C,$A9,Clientes!$L:$L,K$4) -> 0
A10: Cursos | B10: =COUNTIF(Clientes!$C:$C,$A10) -> 6 | C10: =COUNTIFS(Clientes!$C:$C,$A10,Clientes!$B:$B,"A") -> 5 | D10: =COUNTIFS(Clientes!$C:$C,$A10,Clientes!$L:$L,D$4) -> 6 | E10: =COUNTIFS(Clientes!$C:$C,$A10,Clientes!$L:$L,E$4) -> 0 | F10: =COUNTIFS(Clientes!$C:$C,$A10,Clientes!$L:$L,F$4) -> 0 | G10: =COUNTIFS(Clientes!$C:$C,$A10,Clientes!$L:$L,G$4) -> 0 | H10: =COUNTIFS(Clientes!$C:$C,$A10,Clientes!$L:$L,H$4) -> 0 | I10: =COUNTIFS(Clientes!$C:$C,$A10,Clientes!$L:$L,I$4) -> 0 | J10: =COUNTIFS(Clientes!$C:$C,$A10,Clientes!$L:$L,J$4) -> 0 | K10: =COUNTIFS(Clientes!$C:$C,$A10,Clientes!$L:$L,K$4) -> 0
A11: Total | B11: =SUM(B5:B10) -> 49 | C11: =SUM(C5:C10) -> 33 | D11: =SUM(D5:D10) -> 49 | E11: =SUM(E5:E10) -> 0 | F11: =SUM(F5:F10) -> 0 | G11: =SUM(G5:G10) -> 0 | H11: =SUM(H5:H10) -> 0 | I11: =SUM(I5:I10) -> 0 | ... K11: =SUM(K5:K10) -> 0
A13: Taxa de resposta | B13: =IFERROR((F11+G11+H11+I11+J11)/(B11-D11-K11),0) -> 0 | C13: (respondeu ou avançou ÷ contatados, sem contar número errado)
A14: Clientes fechados | B14: =I11 -> 0
A15: Receita mensal (R$49 cada) | B15: =B14*B17 -> 0
A17: Preço do plano (R$) | B17: 49 | C17: Plano Completo da demonstração. Mude aqui se mudar o preço.

Sheet Mensagens
A1: Mensagens prontas
A3: 1. Primeira mensagem | B3: Oi, tudo bem? Encontrei vocês pesquisando [tipo] em [cidade] e curti muito o trabalho! Pergunta rápida: vocês ainda cobram as mensalidades um por um no WhatsApp? (O botão "Abrir" da aba Clientes já manda essa mensagem pronta.)
A4: 2. Se responder sim | B4: Imaginei, quase todo mundo passa por isso! Estou lançando um sistema que cobra sozinho no WhatsApp com o Pix pronto, mostra quem tá devendo e o lucro do mês. Fiz um vídeo de 40 segundos mostrando, posso te mandar?
A5: 3. Junto com o vídeo | B5: Fiz esse vídeo rapidinho mostrando como funciona 👆 Se quiser mexer você mesmo, é só abrir no celular: https://claude.ai/artifact/XKq23zS6CBW4pj5rmbacF9#[tipo] Toca em "Cobrar todos os atrasados" pra ver a mensagem que o aluno recebe. (No final do link: #futebol, #academia, #lutas, #danca, #natacao ou #cursos)
A6: 4. Depois que olhar | B6: O que achou? Quantos alunos vocês têm hoje, mais ou menos?
A7: 5. Fechamento | B7: Com [80] alunos a R$[150], se uns 20% atrasam, são R$[2.400] parados todo mês. O sistema sai R$49/mês. Estou liberando para as 10 primeiras escolas com o 1º mês grátis, e eu mesmo cadastro seus alunos. Quer testar?
A8: Follow-up (2 dias) | B8: Oi! Conseguiu ver o vídeo? 🙂
A9: Último follow-up (+4 dias) | B9: Última mensagem pra não te incomodar: se quiser testar 1 mês grátis, é só me chamar.
A10: Objeção: "tá caro" | B10: Se fizer um único aluno pagar em dia, já se pagou. E o primeiro mês é grátis.
A11: Objeção: "já uso o banco" | B11: O banco gera o Pix, mas não manda a cobrança no WhatsApp de cada aluno, não lembra quem atrasou e não mostra a lista de quem deve. O sistema faz isso sozinho.
A12: Objeção: "vou pensar" | B12: Tranquilo! Posso cadastrar seus alunos sem compromisso, você usa o mês grátis e decide depois?
